This change fixes ``AttributeError`` while running ``pip debug`` since Python 3.13.
